2022-07-11 09:04:58 default[20220711t085709]  inside :-- executable.getExecOutput
2022-07-11 09:04:58 default[20220711t085709]  inside :-- executable.getExecOutput
2022-07-11 09:04:58 default[20220711t085709]  inside :-- executable.getExecOutput
2022-07-11 09:04:58 default[20220711t085709]  inside :-- executable.getExecOutput
2022-07-11 09:04:58 default[20220711t085709]  inside :-- executable.getExecOutput
2022-07-11 09:04:58 default[20220711t085709]  inside :-- executable.getExecOutput
2022-07-11 09:04:58 default[20220711t085709]  inside :-- executable.getExecOutput
2022-07-11 09:04:58 default[20220711t085709]  inside :-- executable.getExecOutput
2022-07-11 09:04:58 default[20220711t085709]  inside :-- executable.getExecOutput
2022-07-11 09:04:58 default[20220711t085709]  inside :-- executable.getExecOutput
2022-07-11 09:04:58 default[20220711t085709]  inside :-- executable.getExecOutput
2022-07-11 09:04:58 default[20220711t085709]  inside :-- executable.getExecOutput
2022-07-11 09:04:58 default[20220711t085709]  inside:   reveal_proc_support.func_groupby_Complete
2022-07-11 09:04:58 default[20220711t085709]  inside:   reveal_proc_support.extracted_part_info
2022-07-11 09:04:58 default[20220711t085709]  inside:   reveal_proc_support.func_agg_start
2022-07-11 09:04:58 default[20220711t085709]  inside aggregation.get_aggregation
2022-07-11 09:04:58 default[20220711t085709]  inside :-- executable.getExecOutput
2022-07-11 09:04:58 default[20220711t085709]  inside :-- executable.getExecOutput
2022-07-11 09:04:58 default[20220711t085709]  inside :-- executable.getExecOutput
2022-07-11 09:04:58 default[20220711t085709]  inside :-- executable.getExecOutput
2022-07-11 09:04:58 default[20220711t085709]  inside :-- executable.getExecOutput
2022-07-11 09:04:58 default[20220711t085709]  inside :-- executable.getExecOutput
2022-07-11 09:04:58 default[20220711t085709]  inside :-- executable.getExecOutput
2022-07-11 09:04:58 default[20220711t085709]  inside:   reveal_proc_support.refine_Query
2022-07-11 09:04:58 default[20220711t085709]  inside:   reveal_proc_support.func_agg_Complete
2022-07-11 09:04:58 default[20220711t085709]  inside:   reveal_proc_support.extracted_part_info
2022-07-11 09:04:58 default[20220711t085709]  inside:   reveal_proc_support.func_orderby_start
2022-07-11 09:04:58 default[20220711t085709]  inside -- orderby_clause.get_orderby_attributes
2022-07-11 09:04:58 default[20220711t085709]  inside -- orderby_clause.generateData
2022-07-11 09:04:58 default[20220711t085709]  inside :-- executable.getExecOutput
2022-07-11 09:04:58 default[20220711t085709]  inside -- orderby_clause.checkOrdering
2022-07-11 09:04:58 default[20220711t085709]  inside :-- executable.getExecOutput
2022-07-11 09:04:58 default[20220711t085709]  inside -- orderby_clause.checkOrdering
2022-07-11 09:04:58 default[20220711t085709]  inside -- orderby_clause.generateData
2022-07-11 09:04:58 default[20220711t085709]  inside :-- executable.getExecOutput
2022-07-11 09:04:58 default[20220711t085709]  inside -- orderby_clause.checkOrdering
2022-07-11 09:04:58 default[20220711t085709]  inside :-- executable.getExecOutput
2022-07-11 09:04:58 default[20220711t085709]  inside -- orderby_clause.checkOrdering
2022-07-11 09:04:58 default[20220711t085709]  inside -- orderby_clause.generateData
2022-07-11 09:04:58 default[20220711t085709]  inside -- orderby_clause.generateData
2022-07-11 09:04:58 default[20220711t085709]  inside -- orderby_clause.generateData
2022-07-11 09:04:58 default[20220711t085709]  inside -- orderby_clause.generateData
2022-07-11 09:04:58 default[20220711t085709]  inside :-- executable.getExecOutput
2022-07-11 09:04:58 default[20220711t085709]  inside -- orderby_clause.generateData
2022-07-11 09:04:58 default[20220711t085709]  inside -- orderby_clause.generateData
2022-07-11 09:04:58 default[20220711t085709]  inside -- orderby_clause.generateData
2022-07-11 09:04:58 default[20220711t085709]  inside -- orderby_clause.generateData
2022-07-11 09:04:58 default[20220711t085709]  inside :-- executable.getExecOutput
2022-07-11 09:04:58 default[20220711t085709]  inside -- orderby_clause.checkOrdering
2022-07-11 09:04:58 default[20220711t085709]  inside :-- executable.getExecOutput
2022-07-11 09:04:58 default[20220711t085709]  inside -- orderby_clause.checkOrdering
2022-07-11 09:04:58 default[20220711t085709]  inside -- orderby_clause.generateData
2022-07-11 09:04:58 default[20220711t085709]  inside :-- executable.getExecOutput
2022-07-11 09:04:58 default[20220711t085709]  inside -- orderby_clause.checkOrdering
2022-07-11 09:04:58 default[20220711t085709]  inside :-- executable.getExecOutput
2022-07-11 09:04:58 default[20220711t085709]  inside -- orderby_clause.checkOrdering
2022-07-11 09:04:58 default[20220711t085709]  inside -- orderby_clause.generateData
2022-07-11 09:04:58 default[20220711t085709]  inside :-- executable.getExecOutput
2022-07-11 09:04:58 default[20220711t085709]  inside:   reveal_proc_support.func_orderby_Complete
2022-07-11 09:04:58 default[20220711t085709]  inside:   reveal_proc_support.extracted_part_info
2022-07-11 09:04:58 default[20220711t085709]  inside:   reveal_proc_support.func_limit_start
2022-07-11 09:04:58 default[20220711t085709]  inside -- limit.get_limit
2022-07-11 09:05:00 default[20220711t085709]  inside :-- executable.getExecOutput
2022-07-11 09:05:00 default[20220711t085709]  inside:   reveal_proc_support.func_limit_Complete
2022-07-11 09:05:00 default[20220711t085709]  inside:   reveal_proc_support.func_assemble_start
2022-07-11 09:05:00 default[20220711t085709]  EXTRACTED OUTPUT QUERY :
2022-07-11 09:05:00 default[20220711t085709]  Select l_returnflag, l_linestatus, Sum(l_quantity) as sum_qty, Sum(l_extendedprice) as sum_base_price, Sum(l_discount) as sum_disc_price, Sum(l_tax) as sum_charge, Avg(l_quantity) as avg_qty, Avg(l_extendedprice) as avg_price, Avg(l_discount) as avg_disc, count(*) as count_order
2022-07-11 09:05:00 default[20220711t085709]  From lineitem
2022-07-11 09:05:00 default[20220711t085709]  Where l_shipdate <= '1998-09-21'
2022-07-11 09:05:00 default[20220711t085709]  Group By l_returnflag, l_linestatus
2022-07-11 09:05:00 default[20220711t085709]  Order By l_returnflag asc, l_linestatus asc
2022-07-11 09:05:00 default[20220711t085709]  Limit ;
2022-07-11 09:05:00 default[20220711t085709]  inside:   reveal_proc_support.func_assemble_Complete
2022-07-11 09:05:00 default[20220711t085709]  end
2022-07-11 09:05:00 default[20220711t085709]  $$$$****$$$$
2022-07-11 09:05:03 default[20220711t083641]  [2022-07-11 09:05:03 +0000] [1] [INFO] Shutting down: Master
2022-07-11 09:05:05 default[20220711t083641]  [2022-07-11 09:05:05 +0000] [1] [INFO] Shutting down: Master
2022-07-11 09:05:26 default[20220708t083931]  ['sneha-354311:asia-south1:postgres']: An error occurred while performing refresh. Scheduling another refresh attempt immediately
2022-07-11 09:05:26 default[20220708t083931]  Traceback (most recent call last):    File "/usr/local/lib/python3.10/site-packages/google/cloud/sql/connector/instance.py", line 410, in _refresh_task      refresh_data = await refresh_task    File "/usr/local/lib/python3.10/site-packages/google/cloud/sql/connector/instance.py", line 344, in _perform_refresh      metadata, ephemeral_cert = await asyncio.gather(    File "/usr/local/lib/python3.10/site-packages/google/cloud/sql/connector/refresh_utils.py", line 98, in _get_metadata      resp = await client_session.get(url, headers=headers, raise_for_status=True)    File "/usr/local/lib/python3.10/site-packages/aiohttp/client.py", line 640, in _request      resp.raise_for_status()    File "/usr/local/lib/python3.10/site-packages/aiohttp/client_reqrep.py", line 1004, in raise_for_status      raise ClientResponseError(  aiohttp.client_exceptions.ClientResponseError: 404, message='Not Found', url=URL('https://sqladmin.googleapis.com/sql/v1beta4/projects/sneha-354311/instances/postgres/connectSettings')
2022-07-11 09:05:26 default[20220708t083931]  Task exception was never retrieved
2022-07-11 09:05:26 default[20220708t083931]  future: <Task finished name='Task-72668' coro=<Instance._schedule_refresh.<locals>._refresh_task() done, defined at /usr/local/lib/python3.10/site-packages/google/cloud/sql/connector/instance.py:399> exception=ClientResponseError(RequestInfo(url=URL('https://sqladmin.googleapis.com/sql/v1beta4/projects/sneha-354311/instances/postgres/connectSettings'), method='GET', headers=<CIMultiDictProxy('Host': 'sqladmin.googleapis.com', 'x-goog-api-client': 'cloud-sql-python-connector/0.6.2+pg8000', 'User-Agent': 'cloud-sql-python-connector/0.6.2+pg8000', 'Content-Type': 'application/json', 'Authorization': 'Bearer ya29.c.b0AXv0zTPq4RBL8oRuPHeWtybUPqe_lMg9HfSolPC_NR9PsaNJzlj-sZFI4w-AZuql3sKPwZUpCosNdbL7gAc3F_nWRq-EPzhXekpPQCQCnpv4C2I9xvvVNEw8guCpgbWV3AqmQzGwqEi5JqQPNegJOdF-LwRxVIut7LhmSYBUdGCVYeUcQIG6l4nfjy_Dt2UFAzzaeqNfYdS8Y6onsg.....................................................................................................................................................................................................................................................................................................................................................................................................................................................................................................................................................................................................................................................................................................................................................................................................................................', 'Accept': '*/*', 'Accept-Encoding': 'gzip, deflate')>, real_url=URL('https://sqladmin.googleapis.com/sql/v1beta4/projects/sneha-354311/instances/postgres/connectSettings')), (), status=404, message='Not Found', headers=<CIMultiDictProxy('Vary': 'Origin', 'Vary': 'X-Origin', 'Vary': 'Referer', 'Content-Type': 'application/json; charset=UTF-8', 'Content-Encoding': 'gzip', 'Date': 'Mon, 11 Jul 2022 09:05:26 GMT', 'Server': 'ESF', 'Cache-Control': 'private', 'X-XSS-Protection': '0', 'X-Frame-Options': 'SAMEORIGIN', 'X-Content-Type-Options': 'nosniff', 'Transfer-Encoding': 'chunked')>)>
2022-07-11 09:05:26 default[20220708t083931]  Traceback (most recent call last):    File "/usr/local/lib/python3.10/site-packages/google/cloud/sql/connector/instance.py", line 430, in _refresh_task      raise e    File "/usr/local/lib/python3.10/site-packages/google/cloud/sql/connector/instance.py", line 410, in _refresh_task      refresh_data = await refresh_task    File "/usr/local/lib/python3.10/site-packages/google/cloud/sql/connector/instance.py", line 344, in _perform_refresh      metadata, ephemeral_cert = await asyncio.gather(    File "/usr/local/lib/python3.10/site-packages/google/cloud/sql/connector/refresh_utils.py", line 98, in _get_metadata      resp = await client_session.get(url, headers=headers, raise_for_status=True)    File "/usr/local/lib/python3.10/site-packages/aiohttp/client.py", line 640, in _request      resp.raise_for_status()    File "/usr/local/lib/python3.10/site-packages/aiohttp/client_reqrep.py", line 1004, in raise_for_status      raise ClientResponseError(  aiohttp.client_exceptions.ClientResponseError: 404, message='Not Found', url=URL('https://sqladmin.googleapis.com/sql/v1beta4/projects/sneha-354311/instances/postgres/connectSettings')
2022-07-11 09:05:56 default[20220708t083931]  ['sneha-354311:asia-south1:postgres']: An error occurred while performing refresh. Scheduling another refresh attempt immediately
2022-07-11 09:05:56 default[20220708t083931]  Traceback (most recent call last):    File "/usr/local/lib/python3.10/site-packages/google/cloud/sql/connector/instance.py", line 410, in _refresh_task      refresh_data = await refresh_task    File "/usr/local/lib/python3.10/site-packages/google/cloud/sql/connector/instance.py", line 344, in _perform_refresh      metadata, ephemeral_cert = await asyncio.gather(    File "/usr/local/lib/python3.10/site-packages/google/cloud/sql/connector/refresh_utils.py", line 98, in _get_metadata      resp = await client_session.get(url, headers=headers, raise_for_status=True)    File "/usr/local/lib/python3.10/site-packages/aiohttp/client.py", line 640, in _request      resp.raise_for_status()    File "/usr/local/lib/python3.10/site-packages/aiohttp/client_reqrep.py", line 1004, in raise_for_status      raise ClientResponseError(  aiohttp.client_exceptions.ClientResponseError: 404, message='Not Found', url=URL('https://sqladmin.googleapis.com/sql/v1beta4/projects/sneha-354311/instances/postgres/connectSettings')
2022-07-11 09:05:56 default[20220708t083931]  Task exception was never retrieved
2022-07-11 09:05:56 default[20220708t083931]  future: <Task finished name='Task-72677' coro=<Instance._schedule_refresh.<locals>._refresh_task() done, defined at /usr/local/lib/python3.10/site-packages/google/cloud/sql/connector/instance.py:399> exception=ClientResponseError(RequestInfo(url=URL('https://sqladmin.googleapis.com/sql/v1beta4/projects/sneha-354311/instances/postgres/connectSettings'), method='GET', headers=<CIMultiDictProxy('Host': 'sqladmin.googleapis.com', 'x-goog-api-client': 'cloud-sql-python-connector/0.6.2+pg8000', 'User-Agent': 'cloud-sql-python-connector/0.6.2+pg8000', 'Content-Type': 'application/json', 'Authorization': 'Bearer ya29.c.b0AXv0zTPq4RBL8oRuPHeWtybUPqe_lMg9HfSolPC_NR9PsaNJzlj-sZFI4w-AZuql3sKPwZUpCosNdbL7gAc3F_nWRq-EPzhXekpPQCQCnpv4C2I9xvvVNEw8guCpgbWV3AqmQzGwqEi5JqQPNegJOdF-LwRxVIut7LhmSYBUdGCVYeUcQIG6l4nfjy_Dt2UFAzzaeqNfYdS8Y6onsg.....................................................................................................................................................................................................................................................................................................................................................................................................................................................................................................................................................................................................................................................................................................................................................................................................................................', 'Accept': '*/*', 'Accept-Encoding': 'gzip, deflate')>, real_url=URL('https://sqladmin.googleapis.com/sql/v1beta4/projects/sneha-354311/instances/postgres/connectSettings')), (), status=404, message='Not Found', headers=<CIMultiDictProxy('Vary': 'Origin', 'Vary': 'X-Origin', 'Vary': 'Referer', 'Content-Type': 'application/json; charset=UTF-8', 'Content-Encoding': 'gzip', 'Date': 'Mon, 11 Jul 2022 09:05:56 GMT', 'Server': 'ESF', 'Cache-Control': 'private', 'X-XSS-Protection': '0', 'X-Frame-Options': 'SAMEORIGIN', 'X-Content-Type-Options': 'nosniff', 'Transfer-Encoding': 'chunked')>)>
2022-07-11 09:05:56 default[20220708t083931]  Traceback (most recent call last):    File "/usr/local/lib/python3.10/site-packages/google/cloud/sql/connector/instance.py", line 430, in _refresh_task      raise e    File "/usr/local/lib/python3.10/site-packages/google/cloud/sql/connector/instance.py", line 410, in _refresh_task      refresh_data = await refresh_task    File "/usr/local/lib/python3.10/site-packages/google/cloud/sql/connector/instance.py", line 344, in _perform_refresh      metadata, ephemeral_cert = await asyncio.gather(    File "/usr/local/lib/python3.10/site-packages/google/cloud/sql/connector/refresh_utils.py", line 98, in _get_metadata      resp = await client_session.get(url, headers=headers, raise_for_status=True)    File "/usr/local/lib/python3.10/site-packages/aiohttp/client.py", line 640, in _request      resp.raise_for_status()    File "/usr/local/lib/python3.10/site-packages/aiohttp/client_reqrep.py", line 1004, in raise_for_status      raise ClientResponseError(  aiohttp.client_exceptions.ClientResponseError: 404, message='Not Found', url=URL('https://sqladmin.googleapis.com/sql/v1beta4/projects/sneha-354311/instances/postgres/connectSettings')
2022-07-11 09:06:26 default[20220708t083931]  ['sneha-354311:asia-south1:postgres']: An error occurred while performing refresh. Scheduling another refresh attempt immediately
2022-07-11 09:06:26 default[20220708t083931]  Traceback (most recent call last):    File "/usr/local/lib/python3.10/site-packages/google/cloud/sql/connector/instance.py", line 410, in _refresh_task      refresh_data = await refresh_task    File "/usr/local/lib/python3.10/site-packages/google/cloud/sql/connector/instance.py", line 344, in _perform_refresh      metadata, ephemeral_cert = await asyncio.gather(    File "/usr/local/lib/python3.10/site-packages/google/cloud/sql/connector/refresh_utils.py", line 176, in _get_ephemeral      resp = await client_session.post(    File "/usr/local/lib/python3.10/site-packages/aiohttp/client.py", line 640, in _request      resp.raise_for_status()    File "/usr/local/lib/python3.10/site-packages/aiohttp/client_reqrep.py", line 1004, in raise_for_status      raise ClientResponseError(  aiohttp.client_exceptions.ClientResponseError: 409, message='Conflict', url=URL('https://sqladmin.googleapis.com/sql/v1beta4/projects/sneha-354311/instances/postgres:generateEphemeralCert')
2022-07-11 09:06:26 default[20220708t083931]  Task exception was never retrieved
2022-07-11 09:06:26 default[20220708t083931]  future: <Task finished name='Task-72686' coro=<Instance._schedule_refresh.<locals>._refresh_task() done, defined at /usr/local/lib/python3.10/site-packages/google/cloud/sql/connector/instance.py:399> exception=ClientResponseError(RequestInfo(url=URL('https://sqladmin.googleapis.com/sql/v1beta4/projects/sneha-354311/instances/postgres:generateEphemeralCert'), method='POST', headers=<CIMultiDictProxy('Host': 'sqladmin.googleapis.com', 'x-goog-api-client': 'cloud-sql-python-connector/0.6.2+pg8000', 'User-Agent': 'cloud-sql-python-connector/0.6.2+pg8000', 'Content-Type': 'application/json', 'Authorization': 'Bearer ya29.c.b0AXv0zTPq4RBL8oRuPHeWtybUPqe_lMg9HfSolPC_NR9PsaNJzlj-sZFI4w-AZuql3sKPwZUpCosNdbL7gAc3F_nWRq-EPzhXekpPQCQCnpv4C2I9xvvVNEw8guCpgbWV3AqmQzGwqEi5JqQPNegJOdF-LwRxVIut7LhmSYBUdGCVYeUcQIG6l4nfjy_Dt2UFAzzaeqNfYdS8Y6onsg.....................................................................................................................................................................................................................................................................................................................................................................................................................................................................................................................................................................................................................................................................................................................................................................................................................................', 'Accept': '*/*', 'Accept-Encoding': 'gzip, deflate', 'Content-Length': '478')>, real_url=URL('https://sqladmin.googleapis.com/sql/v1beta4/projects/sneha-354311/instances/postgres:generateEphemeralCert')), (), status=409, message='Conflict', headers=<CIMultiDictProxy('Vary': 'Origin', 'Vary': 'X-Origin', 'Vary': 'Referer', 'Content-Type': 'application/json; charset=UTF-8', 'Content-Encoding': 'gzip', 'Date': 'Mon, 11 Jul 2022 09:06:26 GMT', 'Server': 'ESF', 'Cache-Control': 'private', 'X-XSS-Protection': '0', 'X-Frame-Options': 'SAMEORIGIN', 'X-Content-Type-Options': 'nosniff', 'Transfer-Encoding': 'chunked')>)>
2022-07-11 09:06:26 default[20220708t083931]  Traceback (most recent call last):    File "/usr/local/lib/python3.10/site-packages/google/cloud/sql/connector/instance.py", line 430, in _refresh_task      raise e    File "/usr/local/lib/python3.10/site-packages/google/cloud/sql/connector/instance.py", line 410, in _refresh_task      refresh_data = await refresh_task    File "/usr/local/lib/python3.10/site-packages/google/cloud/sql/connector/instance.py", line 344, in _perform_refresh      metadata, ephemeral_cert = await asyncio.gather(    File "/usr/local/lib/python3.10/site-packages/google/cloud/sql/connector/refresh_utils.py", line 176, in _get_ephemeral      resp = await client_session.post(    File "/usr/local/lib/python3.10/site-packages/aiohttp/client.py", line 640, in _request      resp.raise_for_status()    File "/usr/local/lib/python3.10/site-packages/aiohttp/client_reqrep.py", line 1004, in raise_for_status      raise ClientResponseError(  aiohttp.client_exceptions.ClientResponseError: 409, message='Conflict', url=URL('https://sqladmin.googleapis.com/sql/v1beta4/projects/sneha-354311/instances/postgres:generateEphemeralCert')
2022-07-11 09:06:56 default[20220708t083931]  ['sneha-354311:asia-south1:postgres']: An error occurred while performing refresh. Scheduling another refresh attempt immediately
2022-07-11 09:06:56 default[20220708t083931]  Traceback (most recent call last):    File "/usr/local/lib/python3.10/site-packages/google/cloud/sql/connector/instance.py", line 410, in _refresh_task      refresh_data = await refresh_task    File "/usr/local/lib/python3.10/site-packages/google/cloud/sql/connector/instance.py", line 344, in _perform_refresh      metadata, ephemeral_cert = await asyncio.gather(    File "/usr/local/lib/python3.10/site-packages/google/cloud/sql/connector/refresh_utils.py", line 98, in _get_metadata      resp = await client_session.get(url, headers=headers, raise_for_status=True)    File "/usr/local/lib/python3.10/site-packages/aiohttp/client.py", line 640, in _request      resp.raise_for_status()    File "/usr/local/lib/python3.10/site-packages/aiohttp/client_reqrep.py", line 1004, in raise_for_status      raise ClientResponseError(  aiohttp.client_exceptions.ClientResponseError: 404, message='Not Found', url=URL('https://sqladmin.googleapis.com/sql/v1beta4/projects/sneha-354311/instances/postgres/connectSettings')
2022-07-11 09:06:56 default[20220708t083931]  Task exception was never retrieved
2022-07-11 09:06:56 default[20220708t083931]  future: <Task finished name='Task-72695' coro=<Instance._schedule_refresh.<locals>._refresh_task() done, defined at /usr/local/lib/python3.10/site-packages/google/cloud/sql/connector/instance.py:399> exception=ClientResponseError(RequestInfo(url=URL('https://sqladmin.googleapis.com/sql/v1beta4/projects/sneha-354311/instances/postgres/connectSettings'), method='GET', headers=<CIMultiDictProxy('Host': 'sqladmin.googleapis.com', 'x-goog-api-client': 'cloud-sql-python-connector/0.6.2+pg8000', 'User-Agent': 'cloud-sql-python-connector/0.6.2+pg8000', 'Content-Type': 'application/json', 'Authorization': 'Bearer ya29.c.b0AXv0zTPq4RBL8oRuPHeWtybUPqe_lMg9HfSolPC_NR9PsaNJzlj-sZFI4w-AZuql3sKPwZUpCosNdbL7gAc3F_nWRq-EPzhXekpPQCQCnpv4C2I9xvvVNEw8guCpgbWV3AqmQzGwqEi5JqQPNegJOdF-LwRxVIut7LhmSYBUdGCVYeUcQIG6l4nfjy_Dt2UFAzzaeqNfYdS8Y6onsg.....................................................................................................................................................................................................................................................................................................................................................................................................................................................................................................................................................................................................................................................................................................................................................................................................................................', 'Accept': '*/*', 'Accept-Encoding': 'gzip, deflate')>, real_url=URL('https://sqladmin.googleapis.com/sql/v1beta4/projects/sneha-354311/instances/postgres/connectSettings')), (), status=404, message='Not Found', headers=<CIMultiDictProxy('Vary': 'Origin', 'Vary': 'X-Origin', 'Vary': 'Referer', 'Content-Type': 'application/json; charset=UTF-8', 'Content-Encoding': 'gzip', 'Date': 'Mon, 11 Jul 2022 09:06:56 GMT', 'Server': 'ESF', 'Cache-Control': 'private', 'X-XSS-Protection': '0', 'X-Frame-Options': 'SAMEORIGIN', 'X-Content-Type-Options': 'nosniff', 'Transfer-Encoding': 'chunked')>)>
2022-07-11 09:06:56 default[20220708t083931]  Traceback (most recent call last):    File "/usr/local/lib/python3.10/site-packages/google/cloud/sql/connector/instance.py", line 430, in _refresh_task      raise e    File "/usr/local/lib/python3.10/site-packages/google/cloud/sql/connector/instance.py", line 410, in _refresh_task      refresh_data = await refresh_task    File "/usr/local/lib/python3.10/site-packages/google/cloud/sql/connector/instance.py", line 344, in _perform_refresh      metadata, ephemeral_cert = await asyncio.gather(    File "/usr/local/lib/python3.10/site-packages/google/cloud/sql/connector/refresh_utils.py", line 98, in _get_metadata      resp = await client_session.get(url, headers=headers, raise_for_status=True)    File "/usr/local/lib/python3.10/site-packages/aiohttp/client.py", line 640, in _request      resp.raise_for_status()    File "/usr/local/lib/python3.10/site-packages/aiohttp/client_reqrep.py", line 1004, in raise_for_status      raise ClientResponseError(  aiohttp.client_exceptions.ClientResponseError: 404, message='Not Found', url=URL('https://sqladmin.googleapis.com/sql/v1beta4/projects/sneha-354311/instances/postgres/connectSettings')
2022-07-11 09:07:26 default[20220708t083931]  ['sneha-354311:asia-south1:postgres']: An error occurred while performing refresh. Scheduling another refresh attempt immediately
2022-07-11 09:07:26 default[20220708t083931]  Traceback (most recent call last):    File "/usr/local/lib/python3.10/site-packages/google/cloud/sql/connector/instance.py", line 410, in _refresh_task      refresh_data = await refresh_task    File "/usr/local/lib/python3.10/site-packages/google/cloud/sql/connector/instance.py", line 344, in _perform_refresh      metadata, ephemeral_cert = await asyncio.gather(    File "/usr/local/lib/python3.10/site-packages/google/cloud/sql/connector/refresh_utils.py", line 176, in _get_ephemeral      resp = await client_session.post(    File "/usr/local/lib/python3.10/site-packages/aiohttp/client.py", line 640, in _request      resp.raise_for_status()    File "/usr/local/lib/python3.10/site-packages/aiohttp/client_reqrep.py", line 1004, in raise_for_status      raise ClientResponseError(  aiohttp.client_exceptions.ClientResponseError: 409, message='Conflict', url=URL('https://sqladmin.googleapis.com/sql/v1beta4/projects/sneha-354311/instances/postgres:generateEphemeralCert')
2022-07-11 09:07:26 default[20220708t083931]  Task exception was never retrieved
2022-07-11 09:07:26 default[20220708t083931]  future: <Task finished name='Task-72704' coro=<Instance._schedule_refresh.<locals>._refresh_task() done, defined at /usr/local/lib/python3.10/site-packages/google/cloud/sql/connector/instance.py:399> exception=ClientResponseError(RequestInfo(url=URL('https://sqladmin.googleapis.com/sql/v1beta4/projects/sneha-354311/instances/postgres:generateEphemeralCert'), method='POST', headers=<CIMultiDictProxy('Host': 'sqladmin.googleapis.com', 'x-goog-api-client': 'cloud-sql-python-connector/0.6.2+pg8000', 'User-Agent': 'cloud-sql-python-connector/0.6.2+pg8000', 'Content-Type': 'application/json', 'Authorization': 'Bearer ya29.c.b0AXv0zTPq4RBL8oRuPHeWtybUPqe_lMg9HfSolPC_NR9PsaNJzlj-sZFI4w-AZuql3sKPwZUpCosNdbL7gAc3F_nWRq-EPzhXekpPQCQCnpv4C2I9xvvVNEw8guCpgbWV3AqmQzGwqEi5JqQPNegJOdF-LwRxVIut7LhmSYBUdGCVYeUcQIG6l4nfjy_Dt2UFAzzaeqNfYdS8Y6onsg.....................................................................................................................................................................................................................................................................................................................................................................................................................................................................................................................................................................................................................................................................................................................................................................................................................................', 'Accept': '*/*', 'Accept-Encoding': 'gzip, deflate', 'Content-Length': '478')>, real_url=URL('https://sqladmin.googleapis.com/sql/v1beta4/projects/sneha-354311/instances/postgres:generateEphemeralCert')), (), status=409, message='Conflict', headers=<CIMultiDictProxy('Vary': 'Origin', 'Vary': 'X-Origin', 'Vary': 'Referer', 'Content-Type': 'application/json; charset=UTF-8', 'Content-Encoding': 'gzip', 'Date': 'Mon, 11 Jul 2022 09:07:26 GMT', 'Server': 'ESF', 'Cache-Control': 'private', 'X-XSS-Protection': '0', 'X-Frame-Options': 'SAMEORIGIN', 'X-Content-Type-Options': 'nosniff', 'Transfer-Encoding': 'chunked')>)>
2022-07-11 09:07:26 default[20220708t083931]  Traceback (most recent call last):    File "/usr/local/lib/python3.10/site-packages/google/cloud/sql/connector/instance.py", line 430, in _refresh_task      raise e    File "/usr/local/lib/python3.10/site-packages/google/cloud/sql/connector/instance.py", line 410, in _refresh_task      refresh_data = await refresh_task    File "/usr/local/lib/python3.10/site-packages/google/cloud/sql/connector/instance.py", line 344, in _perform_refresh      metadata, ephemeral_cert = await asyncio.gather(    File "/usr/local/lib/python3.10/site-packages/google/cloud/sql/connector/refresh_utils.py", line 176, in _get_ephemeral      resp = await client_session.post(    File "/usr/local/lib/python3.10/site-packages/aiohttp/client.py", line 640, in _request      resp.raise_for_status()    File "/usr/local/lib/python3.10/site-packages/aiohttp/client_reqrep.py", line 1004, in raise_for_status      raise ClientResponseError(  aiohttp.client_exceptions.ClientResponseError: 409, message='Conflict', url=URL('https://sqladmin.googleapis.com/sql/v1beta4/projects/sneha-354311/instances/postgres:generateEphemeralCert')
2022-07-11 09:07:56 default[20220708t083931]  ['sneha-354311:asia-south1:postgres']: An error occurred while performing refresh. Scheduling another refresh attempt immediately
2022-07-11 09:07:56 default[20220708t083931]  Traceback (most recent call last):    File "/usr/local/lib/python3.10/site-packages/google/cloud/sql/connector/instance.py", line 410, in _refresh_task      refresh_data = await refresh_task    File "/usr/local/lib/python3.10/site-packages/google/cloud/sql/connector/instance.py", line 344, in _perform_refresh      metadata, ephemeral_cert = await asyncio.gather(    File "/usr/local/lib/python3.10/site-packages/google/cloud/sql/connector/refresh_utils.py", line 98, in _get_metadata      resp = await client_session.get(url, headers=headers, raise_for_status=True)    File "/usr/local/lib/python3.10/site-packages/aiohttp/client.py", line 640, in _request      resp.raise_for_status()    File "/usr/local/lib/python3.10/site-packages/aiohttp/client_reqrep.py", line 1004, in raise_for_status      raise ClientResponseError(  aiohttp.client_exceptions.ClientResponseError: 404, message='Not Found', url=URL('https://sqladmin.googleapis.com/sql/v1beta4/projects/sneha-354311/instances/postgres/connectSettings')
2022-07-11 09:07:56 default[20220708t083931]  Task exception was never retrieved
2022-07-11 09:07:56 default[20220708t083931]  future: <Task finished name='Task-72713' coro=<Instance._schedule_refresh.<locals>._refresh_task() done, defined at /usr/local/lib/python3.10/site-packages/google/cloud/sql/connector/instance.py:399> exception=ClientResponseError(RequestInfo(url=URL('https://sqladmin.googleapis.com/sql/v1beta4/projects/sneha-354311/instances/postgres/connectSettings'), method='GET', headers=<CIMultiDictProxy('Host': 'sqladmin.googleapis.com', 'x-goog-api-client': 'cloud-sql-python-connector/0.6.2+pg8000', 'User-Agent': 'cloud-sql-python-connector/0.6.2+pg8000', 'Content-Type': 'application/json', 'Authorization': 'Bearer ya29.c.b0AXv0zTPq4RBL8oRuPHeWtybUPqe_lMg9HfSolPC_NR9PsaNJzlj-sZFI4w-AZuql3sKPwZUpCosNdbL7gAc3F_nWRq-EPzhXekpPQCQCnpv4C2I9xvvVNEw8guCpgbWV3AqmQzGwqEi5JqQPNegJOdF-LwRxVIut7LhmSYBUdGCVYeUcQIG6l4nfjy_Dt2UFAzzaeqNfYdS8Y6onsg.....................................................................................................................................................................................................................................................................................................................................................................................................................................................................................................................................................................................................................................................................................................................................................................................................................................', 'Accept': '*/*', 'Accept-Encoding': 'gzip, deflate')>, real_url=URL('https://sqladmin.googleapis.com/sql/v1beta4/projects/sneha-354311/instances/postgres/connectSettings')), (), status=404, message='Not Found', headers=<CIMultiDictProxy('Vary': 'Origin', 'Vary': 'X-Origin', 'Vary': 'Referer', 'Content-Type': 'application/json; charset=UTF-8', 'Content-Encoding': 'gzip', 'Date': 'Mon, 11 Jul 2022 09:07:56 GMT', 'Server': 'ESF', 'Cache-Control': 'private', 'X-XSS-Protection': '0', 'X-Frame-Options': 'SAMEORIGIN', 'X-Content-Type-Options': 'nosniff', 'Transfer-Encoding': 'chunked')>)>
2022-07-11 09:07:56 default[20220708t083931]  Traceback (most recent call last):    File "/usr/local/lib/python3.10/site-packages/google/cloud/sql/connector/instance.py", line 430, in _refresh_task      raise e    File "/usr/local/lib/python3.10/site-packages/google/cloud/sql/connector/instance.py", line 410, in _refresh_task      refresh_data = await refresh_task    File "/usr/local/lib/python3.10/site-packages/google/cloud/sql/connector/instance.py", line 344, in _perform_refresh      metadata, ephemeral_cert = await asyncio.gather(    File "/usr/local/lib/python3.10/site-packages/google/cloud/sql/connector/refresh_utils.py", line 98, in _get_metadata      resp = await client_session.get(url, headers=headers, raise_for_status=True)    File "/usr/local/lib/python3.10/site-packages/aiohttp/client.py", line 640, in _request      resp.raise_for_status()    File "/usr/local/lib/python3.10/site-packages/aiohttp/client_reqrep.py", line 1004, in raise_for_status      raise ClientResponseError(  aiohttp.client_exceptions.ClientResponseError: 404, message='Not Found', url=URL('https://sqladmin.googleapis.com/sql/v1beta4/projects/sneha-354311/instances/postgres/connectSettings')
2022-07-11 09:08:26 default[20220708t083931]  ['sneha-354311:asia-south1:postgres']: An error occurred while performing refresh. Scheduling another refresh attempt immediately
2022-07-11 09:08:26 default[20220708t083931]  Traceback (most recent call last):    File "/usr/local/lib/python3.10/site-packages/google/cloud/sql/connector/instance.py", line 410, in _refresh_task      refresh_data = await refresh_task    File "/usr/local/lib/python3.10/site-packages/google/cloud/sql/connector/instance.py", line 344, in _perform_refresh      metadata, ephemeral_cert = await asyncio.gather(    File "/usr/local/lib/python3.10/site-packages/google/cloud/sql/connector/refresh_utils.py", line 98, in _get_metadata      resp = await client_session.get(url, headers=headers, raise_for_status=True)    File "/usr/local/lib/python3.10/site-packages/aiohttp/client.py", line 640, in _request      resp.raise_for_status()    File "/usr/local/lib/python3.10/site-packages/aiohttp/client_reqrep.py", line 1004, in raise_for_status      raise ClientResponseError(  aiohttp.client_exceptions.ClientResponseError: 404, message='Not Found', url=URL('https://sqladmin.googleapis.com/sql/v1beta4/projects/sneha-354311/instances/postgres/connectSettings')
2022-07-11 09:08:26 default[20220708t083931]  Task exception was never retrieved
2022-07-11 09:08:26 default[20220708t083931]  future: <Task finished name='Task-72722' coro=<Instance._schedule_refresh.<locals>._refresh_task() done, defined at /usr/local/lib/python3.10/site-packages/google/cloud/sql/connector/instance.py:399> exception=ClientResponseError(RequestInfo(url=URL('https://sqladmin.googleapis.com/sql/v1beta4/projects/sneha-354311/instances/postgres/connectSettings'), method='GET', headers=<CIMultiDictProxy('Host': 'sqladmin.googleapis.com', 'x-goog-api-client': 'cloud-sql-python-connector/0.6.2+pg8000', 'User-Agent': 'cloud-sql-python-connector/0.6.2+pg8000', 'Content-Type': 'application/json', 'Authorization': 'Bearer ya29.c.b0AXv0zTPq4RBL8oRuPHeWtybUPqe_lMg9HfSolPC_NR9PsaNJzlj-sZFI4w-AZuql3sKPwZUpCosNdbL7gAc3F_nWRq-EPzhXekpPQCQCnpv4C2I9xvvVNEw8guCpgbWV3AqmQzGwqEi5JqQPNegJOdF-LwRxVIut7LhmSYBUdGCVYeUcQIG6l4nfjy_Dt2UFAzzaeqNfYdS8Y6onsg.....................................................................................................................................................................................................................................................................................................................................................................................................................................................................................................................................................................................................................................................................................................................................................................................................................................', 'Accept': '*/*', 'Accept-Encoding': 'gzip, deflate')>, real_url=URL('https://sqladmin.googleapis.com/sql/v1beta4/projects/sneha-354311/instances/postgres/connectSettings')), (), status=404, message='Not Found', headers=<CIMultiDictProxy('Vary': 'Origin', 'Vary': 'X-Origin', 'Vary': 'Referer', 'Content-Type': 'application/json; charset=UTF-8', 'Content-Encoding': 'gzip', 'Date': 'Mon, 11 Jul 2022 09:08:26 GMT', 'Server': 'ESF', 'Cache-Control': 'private', 'X-XSS-Protection': '0', 'X-Frame-Options': 'SAMEORIGIN', 'X-Content-Type-Options': 'nosniff', 'Transfer-Encoding': 'chunked')>)>
2022-07-11 09:08:26 default[20220708t083931]  Traceback (most recent call last):    File "/usr/local/lib/python3.10/site-packages/google/cloud/sql/connector/instance.py", line 430, in _refresh_task      raise e    File "/usr/local/lib/python3.10/site-packages/google/cloud/sql/connector/instance.py", line 410, in _refresh_task      refresh_data = await refresh_task    File "/usr/local/lib/python3.10/site-packages/google/cloud/sql/connector/instance.py", line 344, in _perform_refresh      metadata, ephemeral_cert = await asyncio.gather(    File "/usr/local/lib/python3.10/site-packages/google/cloud/sql/connector/refresh_utils.py", line 98, in _get_metadata      resp = await client_session.get(url, headers=headers, raise_for_status=True)    File "/usr/local/lib/python3.10/site-packages/aiohttp/client.py", line 640, in _request      resp.raise_for_status()    File "/usr/local/lib/python3.10/site-packages/aiohttp/client_reqrep.py", line 1004, in raise_for_status      raise ClientResponseError(  aiohttp.client_exceptions.ClientResponseError: 404, message='Not Found', url=URL('https://sqladmin.googleapis.com/sql/v1beta4/projects/sneha-354311/instances/postgres/connectSettings')
2022-07-11 09:08:56 default[20220708t083931]  ['sneha-354311:asia-south1:postgres']: An error occurred while performing refresh. Scheduling another refresh attempt immediately
2022-07-11 09:08:56 default[20220708t083931]  Traceback (most recent call last):    File "/usr/local/lib/python3.10/site-packages/google/cloud/sql/connector/instance.py", line 410, in _refresh_task      refresh_data = await refresh_task    File "/usr/local/lib/python3.10/site-packages/google/cloud/sql/connector/instance.py", line 344, in _perform_refresh      metadata, ephemeral_cert = await asyncio.gather(    File "/usr/local/lib/python3.10/site-packages/google/cloud/sql/connector/refresh_utils.py", line 98, in _get_metadata      resp = await client_session.get(url, headers=headers, raise_for_status=True)    File "/usr/local/lib/python3.10/site-packages/aiohttp/client.py", line 640, in _request      resp.raise_for_status()    File "/usr/local/lib/python3.10/site-packages/aiohttp/client_reqrep.py", line 1004, in raise_for_status      raise ClientResponseError(  aiohttp.client_exceptions.ClientResponseError: 404, message='Not Found', url=URL('https://sqladmin.googleapis.com/sql/v1beta4/projects/sneha-354311/instances/postgres/connectSettings')
2022-07-11 09:08:56 default[20220708t083931]  Task exception was never retrieved
2022-07-11 09:08:56 default[20220708t083931]  future: <Task finished name='Task-72731' coro=<Instance._schedule_refresh.<locals>._refresh_task() done, defined at /usr/local/lib/python3.10/site-packages/google/cloud/sql/connector/instance.py:399> exception=ClientResponseError(RequestInfo(url=URL('https://sqladmin.googleapis.com/sql/v1beta4/projects/sneha-354311/instances/postgres/connectSettings'), method='GET', headers=<CIMultiDictProxy('Host': 'sqladmin.googleapis.com', 'x-goog-api-client': 'cloud-sql-python-connector/0.6.2+pg8000', 'User-Agent': 'cloud-sql-python-connector/0.6.2+pg8000', 'Content-Type': 'application/json', 'Authorization': 'Bearer ya29.c.b0AXv0zTPq4RBL8oRuPHeWtybUPqe_lMg9HfSolPC_NR9PsaNJzlj-sZFI4w-AZuql3sKPwZUpCosNdbL7gAc3F_nWRq-EPzhXekpPQCQCnpv4C2I9xvvVNEw8guCpgbWV3AqmQzGwqEi5JqQPNegJOdF-LwRxVIut7LhmSYBUdGCVYeUcQIG6l4nfjy_Dt2UFAzzaeqNfYdS8Y6onsg.....................................................................................................................................................................................................................................................................................................................................................................................................................................................................................................................................................................................................................................................................................................................................................................................................................................', 'Accept': '*/*', 'Accept-Encoding': 'gzip, deflate')>, real_url=URL('https://sqladmin.googleapis.com/sql/v1beta4/projects/sneha-354311/instances/postgres/connectSettings')), (), status=404, message='Not Found', headers=<CIMultiDictProxy('Vary': 'Origin', 'Vary': 'X-Origin', 'Vary': 'Referer', 'Content-Type': 'application/json; charset=UTF-8', 'Content-Encoding': 'gzip', 'Date': 'Mon, 11 Jul 2022 09:08:56 GMT', 'Server': 'ESF', 'Cache-Control': 'private', 'X-XSS-Protection': '0', 'X-Frame-Options': 'SAMEORIGIN', 'X-Content-Type-Options': 'nosniff', 'Transfer-Encoding': 'chunked')>)>
2022-07-11 09:08:56 default[20220708t083931]  Traceback (most recent call last):    File "/usr/local/lib/python3.10/site-packages/google/cloud/sql/connector/instance.py", line 430, in _refresh_task      raise e    File "/usr/local/lib/python3.10/site-packages/google/cloud/sql/connector/instance.py", line 410, in _refresh_task      refresh_data = await refresh_task    File "/usr/local/lib/python3.10/site-packages/google/cloud/sql/connector/instance.py", line 344, in _perform_refresh      metadata, ephemeral_cert = await asyncio.gather(    File "/usr/local/lib/python3.10/site-packages/google/cloud/sql/connector/refresh_utils.py", line 98, in _get_metadata      resp = await client_session.get(url, headers=headers, raise_for_status=True)    File "/usr/local/lib/python3.10/site-packages/aiohttp/client.py", line 640, in _request      resp.raise_for_status()    File "/usr/local/lib/python3.10/site-packages/aiohttp/client_reqrep.py", line 1004, in raise_for_status      raise ClientResponseError(  aiohttp.client_exceptions.ClientResponseError: 404, message='Not Found', url=URL('https://sqladmin.googleapis.com/sql/v1beta4/projects/sneha-354311/instances/postgres/connectSettings')
2022-07-11 09:09:26 default[20220708t083931]  ['sneha-354311:asia-south1:postgres']: An error occurred while performing refresh. Scheduling another refresh attempt immediately
2022-07-11 09:09:26 default[20220708t083931]  Traceback (most recent call last):    File "/usr/local/lib/python3.10/site-packages/google/cloud/sql/connector/instance.py", line 410, in _refresh_task      refresh_data = await refresh_task    File "/usr/local/lib/python3.10/site-packages/google/cloud/sql/connector/instance.py", line 344, in _perform_refresh      metadata, ephemeral_cert = await asyncio.gather(    File "/usr/local/lib/python3.10/site-packages/google/cloud/sql/connector/refresh_utils.py", line 98, in _get_metadata      resp = await client_session.get(url, headers=headers, raise_for_status=True)    File "/usr/local/lib/python3.10/site-packages/aiohttp/client.py", line 640, in _request      resp.raise_for_status()    File "/usr/local/lib/python3.10/site-packages/aiohttp/client_reqrep.py", line 1004, in raise_for_status      raise ClientResponseError(  aiohttp.client_exceptions.ClientResponseError: 404, message='Not Found', url=URL('https://sqladmin.googleapis.com/sql/v1beta4/projects/sneha-354311/instances/postgres/connectSettings')
2022-07-11 09:09:26 default[20220708t083931]  Task exception was never retrieved
2022-07-11 09:09:26 default[20220708t083931]  future: <Task finished name='Task-72740' coro=<Instance._schedule_refresh.<locals>._refresh_task() done, defined at /usr/local/lib/python3.10/site-packages/google/cloud/sql/connector/instance.py:399> exception=ClientResponseError(RequestInfo(url=URL('https://sqladmin.googleapis.com/sql/v1beta4/projects/sneha-354311/instances/postgres/connectSettings'), method='GET', headers=<CIMultiDictProxy('Host': 'sqladmin.googleapis.com', 'x-goog-api-client': 'cloud-sql-python-connector/0.6.2+pg8000', 'User-Agent': 'cloud-sql-python-connector/0.6.2+pg8000', 'Content-Type': 'application/json', 'Authorization': 'Bearer ya29.c.b0AXv0zTPq4RBL8oRuPHeWtybUPqe_lMg9HfSolPC_NR9PsaNJzlj-sZFI4w-AZuql3sKPwZUpCosNdbL7gAc3F_nWRq-EPzhXekpPQCQCnpv4C2I9xvvVNEw8guCpgbWV3AqmQzGwqEi5JqQPNegJOdF-LwRxVIut7LhmSYBUdGCVYeUcQIG6l4nfjy_Dt2UFAzzaeqNfYdS8Y6onsg.....................................................................................................................................................................................................................................................................................................................................................................................................................................................................................................................................................................................................................................................................................................................................................................................................................................', 'Accept': '*/*', 'Accept-Encoding': 'gzip, deflate')>, real_url=URL('https://sqladmin.googleapis.com/sql/v1beta4/projects/sneha-354311/instances/postgres/connectSettings')), (), status=404, message='Not Found', headers=<CIMultiDictProxy('Vary': 'Origin', 'Vary': 'X-Origin', 'Vary': 'Referer', 'Content-Type': 'application/json; charset=UTF-8', 'Content-Encoding': 'gzip', 'Date': 'Mon, 11 Jul 2022 09:09:26 GMT', 'Server': 'ESF', 'Cache-Control': 'private', 'X-XSS-Protection': '0', 'X-Frame-Options': 'SAMEORIGIN', 'X-Content-Type-Options': 'nosniff', 'Transfer-Encoding': 'chunked')>)>
2022-07-11 09:09:26 default[20220708t083931]  Traceback (most recent call last):    File "/usr/local/lib/python3.10/site-packages/google/cloud/sql/connector/instance.py", line 430, in _refresh_task      raise e    File "/usr/local/lib/python3.10/site-packages/google/cloud/sql/connector/instance.py", line 410, in _refresh_task      refresh_data = await refresh_task    File "/usr/local/lib/python3.10/site-packages/google/cloud/sql/connector/instance.py", line 344, in _perform_refresh      metadata, ephemeral_cert = await asyncio.gather(    File "/usr/local/lib/python3.10/site-packages/google/cloud/sql/connector/refresh_utils.py", line 98, in _get_metadata      resp = await client_session.get(url, headers=headers, raise_for_status=True)    File "/usr/local/lib/python3.10/site-packages/aiohttp/client.py", line 640, in _request      resp.raise_for_status()    File "/usr/local/lib/python3.10/site-packages/aiohttp/client_reqrep.py", line 1004, in raise_for_status      raise ClientResponseError(  aiohttp.client_exceptions.ClientResponseError: 404, message='Not Found', url=URL('https://sqladmin.googleapis.com/sql/v1beta4/projects/sneha-354311/instances/postgres/connectSettings')
2022-07-11 09:09:56 default[20220708t083931]  ['sneha-354311:asia-south1:postgres']: An error occurred while performing refresh. Scheduling another refresh attempt immediately
2022-07-11 09:09:56 default[20220708t083931]  Traceback (most recent call last):    File "/usr/local/lib/python3.10/site-packages/google/cloud/sql/connector/instance.py", line 410, in _refresh_task      refresh_data = await refresh_task    File "/usr/local/lib/python3.10/site-packages/google/cloud/sql/connector/instance.py", line 344, in _perform_refresh      metadata, ephemeral_cert = await asyncio.gather(    File "/usr/local/lib/python3.10/site-packages/google/cloud/sql/connector/refresh_utils.py", line 176, in _get_ephemeral      resp = await client_session.post(    File "/usr/local/lib/python3.10/site-packages/aiohttp/client.py", line 640, in _request      resp.raise_for_status()    File "/usr/local/lib/python3.10/site-packages/aiohttp/client_reqrep.py", line 1004, in raise_for_status      raise ClientResponseError(  aiohttp.client_exceptions.ClientResponseError: 409, message='Conflict', url=URL('https://sqladmin.googleapis.com/sql/v1beta4/projects/sneha-354311/instances/postgres:generateEphemeralCert')
2022-07-11 09:09:56 default[20220708t083931]  Task exception was never retrieved
2022-07-11 09:09:56 default[20220708t083931]  future: <Task finished name='Task-72749' coro=<Instance._schedule_refresh.<locals>._refresh_task() done, defined at /usr/local/lib/python3.10/site-packages/google/cloud/sql/connector/instance.py:399> exception=ClientResponseError(RequestInfo(url=URL('https://sqladmin.googleapis.com/sql/v1beta4/projects/sneha-354311/instances/postgres:generateEphemeralCert'), method='POST', headers=<CIMultiDictProxy('Host': 'sqladmin.googleapis.com', 'x-goog-api-client': 'cloud-sql-python-connector/0.6.2+pg8000', 'User-Agent': 'cloud-sql-python-connector/0.6.2+pg8000', 'Content-Type': 'application/json', 'Authorization': 'Bearer ya29.c.b0AXv0zTPq4RBL8oRuPHeWtybUPqe_lMg9HfSolPC_NR9PsaNJzlj-sZFI4w-AZuql3sKPwZUpCosNdbL7gAc3F_nWRq-EPzhXekpPQCQCnpv4C2I9xvvVNEw8guCpgbWV3AqmQzGwqEi5JqQPNegJOdF-LwRxVIut7LhmSYBUdGCVYeUcQIG6l4nfjy_Dt2UFAzzaeqNfYdS8Y6onsg.....................................................................................................................................................................................................................................................................................................................................................................................................................................................................................................................................................................................................................................................................................................................................................................................................................................', 'Accept': '*/*', 'Accept-Encoding': 'gzip, deflate', 'Content-Length': '478')>, real_url=URL('https://sqladmin.googleapis.com/sql/v1beta4/projects/sneha-354311/instances/postgres:generateEphemeralCert')), (), status=409, message='Conflict', headers=<CIMultiDictProxy('Vary': 'Origin', 'Vary': 'X-Origin', 'Vary': 'Referer', 'Content-Type': 'application/json; charset=UTF-8', 'Content-Encoding': 'gzip', 'Date': 'Mon, 11 Jul 2022 09:09:56 GMT', 'Server': 'ESF', 'Cache-Control': 'private', 'X-XSS-Protection': '0', 'X-Frame-Options': 'SAMEORIGIN', 'X-Content-Type-Options': 'nosniff', 'Transfer-Encoding': 'chunked')>)>
2022-07-11 09:09:56 default[20220708t083931]  Traceback (most recent call last):    File "/usr/local/lib/python3.10/site-packages/google/cloud/sql/connector/instance.py", line 430, in _refresh_task      raise e    File "/usr/local/lib/python3.10/site-packages/google/cloud/sql/connector/instance.py", line 410, in _refresh_task      refresh_data = await refresh_task    File "/usr/local/lib/python3.10/site-packages/google/cloud/sql/connector/instance.py", line 344, in _perform_refresh      metadata, ephemeral_cert = await asyncio.gather(    File "/usr/local/lib/python3.10/site-packages/google/cloud/sql/connector/refresh_utils.py", line 176, in _get_ephemeral      resp = await client_session.post(    File "/usr/local/lib/python3.10/site-packages/aiohttp/client.py", line 640, in _request      resp.raise_for_status()    File "/usr/local/lib/python3.10/site-packages/aiohttp/client_reqrep.py", line 1004, in raise_for_status      raise ClientResponseError(  aiohttp.client_exceptions.ClientResponseError: 409, message='Conflict', url=URL('https://sqladmin.googleapis.com/sql/v1beta4/projects/sneha-354311/instances/postgres:generateEphemeralCert')
2022-07-11 09:10:26 default[20220708t083931]  ['sneha-354311:asia-south1:postgres']: An error occurred while performing refresh. Scheduling another refresh attempt immediately
2022-07-11 09:10:26 default[20220708t083931]  Traceback (most recent call last):    File "/usr/local/lib/python3.10/site-packages/google/cloud/sql/connector/instance.py", line 410, in _refresh_task      refresh_data = await refresh_task    File "/usr/local/lib/python3.10/site-packages/google/cloud/sql/connector/instance.py", line 344, in _perform_refresh      metadata, ephemeral_cert = await asyncio.gather(    File "/usr/local/lib/python3.10/site-packages/google/cloud/sql/connector/refresh_utils.py", line 98, in _get_metadata      resp = await client_session.get(url, headers=headers, raise_for_status=True)    File "/usr/local/lib/python3.10/site-packages/aiohttp/client.py", line 640, in _request      resp.raise_for_status()    File "/usr/local/lib/python3.10/site-packages/aiohttp/client_reqrep.py", line 1004, in raise_for_status      raise ClientResponseError(  aiohttp.client_exceptions.ClientResponseError: 404, message='Not Found', url=URL('https://sqladmin.googleapis.com/sql/v1beta4/projects/sneha-354311/instances/postgres/connectSettings')
2022-07-11 09:10:26 default[20220708t083931]  Task exception was never retrieved
2022-07-11 09:10:26 default[20220708t083931]  future: <Task finished name='Task-72758' coro=<Instance._schedule_refresh.<locals>._refresh_task() done, defined at /usr/local/lib/python3.10/site-packages/google/cloud/sql/connector/instance.py:399> exception=ClientResponseError(RequestInfo(url=URL('https://sqladmin.googleapis.com/sql/v1beta4/projects/sneha-354311/instances/postgres/connectSettings'), method='GET', headers=<CIMultiDictProxy('Host': 'sqladmin.googleapis.com', 'x-goog-api-client': 'cloud-sql-python-connector/0.6.2+pg8000', 'User-Agent': 'cloud-sql-python-connector/0.6.2+pg8000', 'Content-Type': 'application/json', 'Authorization': 'Bearer ya29.c.b0AXv0zTPq4RBL8oRuPHeWtybUPqe_lMg9HfSolPC_NR9PsaNJzlj-sZFI4w-AZuql3sKPwZUpCosNdbL7gAc3F_nWRq-EPzhXekpPQCQCnpv4C2I9xvvVNEw8guCpgbWV3AqmQzGwqEi5JqQPNegJOdF-LwRxVIut7LhmSYBUdGCVYeUcQIG6l4nfjy_Dt2UFAzzaeqNfYdS8Y6onsg.....................................................................................................................................................................................................................................................................................................................................................................................................................................................................................................................................................................................................................................................................................................................................................................................................................................', 'Accept': '*/*', 'Accept-Encoding': 'gzip, deflate')>, real_url=URL('https://sqladmin.googleapis.com/sql/v1beta4/projects/sneha-354311/instances/postgres/connectSettings')), (), status=404, message='Not Found', headers=<CIMultiDictProxy('Vary': 'Origin', 'Vary': 'X-Origin', 'Vary': 'Referer', 'Content-Type': 'application/json; charset=UTF-8', 'Content-Encoding': 'gzip', 'Date': 'Mon, 11 Jul 2022 09:10:26 GMT', 'Server': 'ESF', 'Cache-Control': 'private', 'X-XSS-Protection': '0', 'X-Frame-Options': 'SAMEORIGIN', 'X-Content-Type-Options': 'nosniff', 'Transfer-Encoding': 'chunked')>)>
2022-07-11 09:10:26 default[20220708t083931]  Traceback (most recent call last):    File "/usr/local/lib/python3.10/site-packages/google/cloud/sql/connector/instance.py", line 430, in _refresh_task      raise e    File "/usr/local/lib/python3.10/site-packages/google/cloud/sql/connector/instance.py", line 410, in _refresh_task      refresh_data = await refresh_task    File "/usr/local/lib/python3.10/site-packages/google/cloud/sql/connector/instance.py", line 344, in _perform_refresh      metadata, ephemeral_cert = await asyncio.gather(    File "/usr/local/lib/python3.10/site-packages/google/cloud/sql/connector/refresh_utils.py", line 98, in _get_metadata      resp = await client_session.get(url, headers=headers, raise_for_status=True)    File "/usr/local/lib/python3.10/site-packages/aiohttp/client.py", line 640, in _request      resp.raise_for_status()    File "/usr/local/lib/python3.10/site-packages/aiohttp/client_reqrep.py", line 1004, in raise_for_status      raise ClientResponseError(  aiohttp.client_exceptions.ClientResponseError: 404, message='Not Found', url=URL('https://sqladmin.googleapis.com/sql/v1beta4/projects/sneha-354311/instances/postgres/connectSettings')
2022-07-11 09:10:56 default[20220708t083931]  ['sneha-354311:asia-south1:postgres']: An error occurred while performing refresh. Scheduling another refresh attempt immediately
2022-07-11 09:10:56 default[20220708t083931]  Traceback (most recent call last):    File "/usr/local/lib/python3.10/site-packages/google/cloud/sql/connector/instance.py", line 410, in _refresh_task      refresh_data = await refresh_task    File "/usr/local/lib/python3.10/site-packages/google/cloud/sql/connector/instance.py", line 344, in _perform_refresh      metadata, ephemeral_cert = await asyncio.gather(    File "/usr/local/lib/python3.10/site-packages/google/cloud/sql/connector/refresh_utils.py", line 98, in _get_metadata      resp = await client_session.get(url, headers=headers, raise_for_status=True)    File "/usr/local/lib/python3.10/site-packages/aiohttp/client.py", line 640, in _request      resp.raise_for_status()    File "/usr/local/lib/python3.10/site-packages/aiohttp/client_reqrep.py", line 1004, in raise_for_status      raise ClientResponseError(  aiohttp.client_exceptions.ClientResponseError: 404, message='Not Found', url=URL('https://sqladmin.googleapis.com/sql/v1beta4/projects/sneha-354311/instances/postgres/connectSettings')
2022-07-11 09:10:56 default[20220708t083931]  Task exception was never retrieved
2022-07-11 09:10:56 default[20220708t083931]  future: <Task finished name='Task-72767' coro=<Instance._schedule_refresh.<locals>._refresh_task() done, defined at /usr/local/lib/python3.10/site-packages/google/cloud/sql/connector/instance.py:399> exception=ClientResponseError(RequestInfo(url=URL('https://sqladmin.googleapis.com/sql/v1beta4/projects/sneha-354311/instances/postgres/connectSettings'), method='GET', headers=<CIMultiDictProxy('Host': 'sqladmin.googleapis.com', 'x-goog-api-client': 'cloud-sql-python-connector/0.6.2+pg8000', 'User-Agent': 'cloud-sql-python-connector/0.6.2+pg8000', 'Content-Type': 'application/json', 'Authorization': 'Bearer ya29.c.b0AXv0zTPq4RBL8oRuPHeWtybUPqe_lMg9HfSolPC_NR9PsaNJzlj-sZFI4w-AZuql3sKPwZUpCosNdbL7gAc3F_nWRq-EPzhXekpPQCQCnpv4C2I9xvvVNEw8guCpgbWV3AqmQzGwqEi5JqQPNegJOdF-LwRxVIut7LhmSYBUdGCVYeUcQIG6l4nfjy_Dt2UFAzzaeqNfYdS8Y6onsg.....................................................................................................................................................................................................................................................................................................................................................................................................................................................................................................................................................................................................................................................................................................................................................................................................................................', 'Accept': '*/*', 'Accept-Encoding': 'gzip, deflate')>, real_url=URL('https://sqladmin.googleapis.com/sql/v1beta4/projects/sneha-354311/instances/postgres/connectSettings')), (), status=404, message='Not Found', headers=<CIMultiDictProxy('Vary': 'Origin', 'Vary': 'X-Origin', 'Vary': 'Referer', 'Content-Type': 'application/json; charset=UTF-8', 'Content-Encoding': 'gzip', 'Date': 'Mon, 11 Jul 2022 09:10:56 GMT', 'Server': 'ESF', 'Cache-Control': 'private', 'X-XSS-Protection': '0', 'X-Frame-Options': 'SAMEORIGIN', 'X-Content-Type-Options': 'nosniff', 'Transfer-Encoding': 'chunked')>)>
2022-07-11 09:10:56 default[20220708t083931]  Traceback (most recent call last):    File "/usr/local/lib/python3.10/site-packages/google/cloud/sql/connector/instance.py", line 430, in _refresh_task      raise e    File "/usr/local/lib/python3.10/site-packages/google/cloud/sql/connector/instance.py", line 410, in _refresh_task      refresh_data = await refresh_task    File "/usr/local/lib/python3.10/site-packages/google/cloud/sql/connector/instance.py", line 344, in _perform_refresh      metadata, ephemeral_cert = await asyncio.gather(    File "/usr/local/lib/python3.10/site-packages/google/cloud/sql/connector/refresh_utils.py", line 98, in _get_metadata      resp = await client_session.get(url, headers=headers, raise_for_status=True)    File "/usr/local/lib/python3.10/site-packages/aiohttp/client.py", line 640, in _request      resp.raise_for_status()    File "/usr/local/lib/python3.10/site-packages/aiohttp/client_reqrep.py", line 1004, in raise_for_status      raise ClientResponseError(  aiohttp.client_exceptions.ClientResponseError: 404, message='Not Found', url=URL('https://sqladmin.googleapis.com/sql/v1beta4/projects/sneha-354311/instances/postgres/connectSettings')
2022-07-11 09:11:26 default[20220708t083931]  ['sneha-354311:asia-south1:postgres']: An error occurred while performing refresh. Scheduling another refresh attempt immediately
2022-07-11 09:11:26 default[20220708t083931]  Traceback (most recent call last):    File "/usr/local/lib/python3.10/site-packages/google/cloud/sql/connector/instance.py", line 410, in _refresh_task      refresh_data = await refresh_task    File "/usr/local/lib/python3.10/site-packages/google/cloud/sql/connector/instance.py", line 344, in _perform_refresh      metadata, ephemeral_cert = await asyncio.gather(    File "/usr/local/lib/python3.10/site-packages/google/cloud/sql/connector/refresh_utils.py", line 98, in _get_metadata      resp = await client_session.get(url, headers=headers, raise_for_status=True)    File "/usr/local/lib/python3.10/site-packages/aiohttp/client.py", line 640, in _request      resp.raise_for_status()    File "/usr/local/lib/python3.10/site-packages/aiohttp/client_reqrep.py", line 1004, in raise_for_status      raise ClientResponseError(  aiohttp.client_exceptions.ClientResponseError: 404, message='Not Found', url=URL('https://sqladmin.googleapis.com/sql/v1beta4/projects/sneha-354311/instances/postgres/connectSettings')
2022-07-11 09:11:26 default[20220708t083931]  Task exception was never retrieved
2022-07-11 09:11:26 default[20220708t083931]  future: <Task finished name='Task-72776' coro=<Instance._schedule_refresh.<locals>._refresh_task() done, defined at /usr/local/lib/python3.10/site-packages/google/cloud/sql/connector/instance.py:399> exception=ClientResponseError(RequestInfo(url=URL('https://sqladmin.googleapis.com/sql/v1beta4/projects/sneha-354311/instances/postgres/connectSettings'), method='GET', headers=<CIMultiDictProxy('Host': 'sqladmin.googleapis.com', 'x-goog-api-client': 'cloud-sql-python-connector/0.6.2+pg8000', 'User-Agent': 'cloud-sql-python-connector/0.6.2+pg8000', 'Content-Type': 'application/json', 'Authorization': 'Bearer ya29.c.b0AXv0zTPq4RBL8oRuPHeWtybUPqe_lMg9HfSolPC_NR9PsaNJzlj-sZFI4w-AZuql3sKPwZUpCosNdbL7gAc3F_nWRq-EPzhXekpPQCQCnpv4C2I9xvvVNEw8guCpgbWV3AqmQzGwqEi5JqQPNegJOdF-LwRxVIut7LhmSYBUdGCVYeUcQIG6l4nfjy_Dt2UFAzzaeqNfYdS8Y6onsg.....................................................................................................................................................................................................................................................................................................................................................................................................................................................................................................................................................................................................................................................................................................................................................................................................................................', 'Accept': '*/*', 'Accept-Encoding': 'gzip, deflate')>, real_url=URL('https://sqladmin.googleapis.com/sql/v1beta4/projects/sneha-354311/instances/postgres/connectSettings')), (), status=404, message='Not Found', headers=<CIMultiDictProxy('Vary': 'Origin', 'Vary': 'X-Origin', 'Vary': 'Referer', 'Content-Type': 'application/json; charset=UTF-8', 'Content-Encoding': 'gzip', 'Date': 'Mon, 11 Jul 2022 09:11:26 GMT', 'Server': 'ESF', 'Cache-Control': 'private', 'X-XSS-Protection': '0', 'X-Frame-Options': 'SAMEORIGIN', 'X-Content-Type-Options': 'nosniff', 'Transfer-Encoding': 'chunked')>)>
2022-07-11 09:11:26 default[20220708t083931]  Traceback (most recent call last):    File "/usr/local/lib/python3.10/site-packages/google/cloud/sql/connector/instance.py", line 430, in _refresh_task      raise e    File "/usr/local/lib/python3.10/site-packages/google/cloud/sql/connector/instance.py", line 410, in _refresh_task      refresh_data = await refresh_task    File "/usr/local/lib/python3.10/site-packages/google/cloud/sql/connector/instance.py", line 344, in _perform_refresh      metadata, ephemeral_cert = await asyncio.gather(    File "/usr/local/lib/python3.10/site-packages/google/cloud/sql/connector/refresh_utils.py", line 98, in _get_metadata      resp = await client_session.get(url, headers=headers, raise_for_status=True)    File "/usr/local/lib/python3.10/site-packages/aiohttp/client.py", line 640, in _request      resp.raise_for_status()    File "/usr/local/lib/python3.10/site-packages/aiohttp/client_reqrep.py", line 1004, in raise_for_status      raise ClientResponseError(  aiohttp.client_exceptions.ClientResponseError: 404, message='Not Found', url=URL('https://sqladmin.googleapis.com/sql/v1beta4/projects/sneha-354311/instances/postgres/connectSettings')
2022-07-11 09:11:40 default[20220711t085709]  inside------reveal_support.init
2022-07-11 09:11:40 default[20220711t085709]  inside------reveal_support.establishConnection
2022-07-11 09:11:40 default[20220711t085709]  The global `connect` method is deprecated and may be removed in a later version. Please initialize a `Connector` object and call it's `connect` method directly.
2022-07-11 09:11:40 default[20220711t085709]  See https://github.com/GoogleCloudPlatform/cloud-sql-python-connector/blob/main/README.md#how-to-use-this-connector for examples.
2022-07-11 09:11:40 default[20220711t085709]  connected...
2022-07-11 09:11:43 default[20220711t085709]  "GET /turbo-stream" 101
2022-07-11 09:11:48 default[20220711t085709]  "GET /query_output_page" 499
2022-07-11 09:11:56 default[20220708t083931]  ['sneha-354311:asia-south1:postgres']: An error occurred while performing refresh. Scheduling another refresh attempt immediately
2022-07-11 09:11:56 default[20220708t083931]  Traceback (most recent call last):    File "/usr/local/lib/python3.10/site-packages/google/cloud/sql/connector/instance.py", line 410, in _refresh_task      refresh_data = await refresh_task    File "/usr/local/lib/python3.10/site-packages/google/cloud/sql/connector/instance.py", line 344, in _perform_refresh      metadata, ephemeral_cert = await asyncio.gather(    File "/usr/local/lib/python3.10/site-packages/google/cloud/sql/connector/refresh_utils.py", line 98, in _get_metadata      resp = await client_session.get(url, headers=headers, raise_for_status=True)    File "/usr/local/lib/python3.10/site-packages/aiohttp/client.py", line 640, in _request      resp.raise_for_status()    File "/usr/local/lib/python3.10/site-packages/aiohttp/client_reqrep.py", line 1004, in raise_for_status      raise ClientResponseError(  aiohttp.client_exceptions.ClientResponseError: 404, message='Not Found', url=URL('https://sqladmin.googleapis.com/sql/v1beta4/projects/sneha-354311/instances/postgres/connectSettings')
2022-07-11 09:11:56 default[20220708t083931]  Task exception was never retrieved
2022-07-11 09:11:56 default[20220708t083931]  future: <Task finished name='Task-72785' coro=<Instance._schedule_refresh.<locals>._refresh_task() done, defined at /usr/local/lib/python3.10/site-packages/google/cloud/sql/connector/instance.py:399> exception=ClientResponseError(RequestInfo(url=URL('https://sqladmin.googleapis.com/sql/v1beta4/projects/sneha-354311/instances/postgres/connectSettings'), method='GET', headers=<CIMultiDictProxy('Host': 'sqladmin.googleapis.com', 'x-goog-api-client': 'cloud-sql-python-connector/0.6.2+pg8000', 'User-Agent': 'cloud-sql-python-connector/0.6.2+pg8000', 'Content-Type': 'application/json', 'Authorization': 'Bearer ya29.c.b0AXv0zTPq4RBL8oRuPHeWtybUPqe_lMg9HfSolPC_NR9PsaNJzlj-sZFI4w-AZuql3sKPwZUpCosNdbL7gAc3F_nWRq-EPzhXekpPQCQCnpv4C2I9xvvVNEw8guCpgbWV3AqmQzGwqEi5JqQPNegJOdF-LwRxVIut7LhmSYBUdGCVYeUcQIG6l4nfjy_Dt2UFAzzaeqNfYdS8Y6onsg.....................................................................................................................................................................................................................................................................................................................................................................................................................................................................................................................................................................................................................................................................................................................................................................................................................................', 'Accept': '*/*', 'Accept-Encoding': 'gzip, deflate')>, real_url=URL('https://sqladmin.googleapis.com/sql/v1beta4/projects/sneha-354311/instances/postgres/connectSettings')), (), status=404, message='Not Found', headers=<CIMultiDictProxy('Vary': 'Origin', 'Vary': 'X-Origin', 'Vary': 'Referer', 'Content-Type': 'application/json; charset=UTF-8', 'Content-Encoding': 'gzip', 'Date': 'Mon, 11 Jul 2022 09:11:56 GMT', 'Server': 'ESF', 'Cache-Control': 'private', 'X-XSS-Protection': '0', 'X-Frame-Options': 'SAMEORIGIN', 'X-Content-Type-Options': 'nosniff', 'Transfer-Encoding': 'chunked')>)>
2022-07-11 09:11:56 default[20220708t083931]  Traceback (most recent call last):    File "/usr/local/lib/python3.10/site-packages/google/cloud/sql/connector/instance.py", line 430, in _refresh_task      raise e    File "/usr/local/lib/python3.10/site-packages/google/cloud/sql/connector/instance.py", line 410, in _refresh_task      refresh_data = await refresh_task    File "/usr/local/lib/python3.10/site-packages/google/cloud/sql/connector/instance.py", line 344, in _perform_refresh      metadata, ephemeral_cert = await asyncio.gather(    File "/usr/local/lib/python3.10/site-packages/google/cloud/sql/connector/refresh_utils.py", line 98, in _get_metadata      resp = await client_session.get(url, headers=headers, raise_for_status=True)    File "/usr/local/lib/python3.10/site-packages/aiohttp/client.py", line 640, in _request      resp.raise_for_status()    File "/usr/local/lib/python3.10/site-packages/aiohttp/client_reqrep.py", line 1004, in raise_for_status      raise ClientResponseError(  aiohttp.client_exceptions.ClientResponseError: 404, message='Not Found', url=URL('https://sqladmin.googleapis.com/sql/v1beta4/projects/sneha-354311/instances/postgres/connectSettings')
2022-07-11 09:12:26 default[20220708t083931]  ['sneha-354311:asia-south1:postgres']: An error occurred while performing refresh. Scheduling another refresh attempt immediately
2022-07-11 09:12:26 default[20220708t083931]  Traceback (most recent call last):    File "/usr/local/lib/python3.10/site-packages/google/cloud/sql/connector/instance.py", line 410, in _refresh_task      refresh_data = await refresh_task    File "/usr/local/lib/python3.10/site-packages/google/cloud/sql/connector/instance.py", line 344, in _perform_refresh      metadata, ephemeral_cert = await asyncio.gather(    File "/usr/local/lib/python3.10/site-packages/google/cloud/sql/connector/refresh_utils.py", line 98, in _get_metadata      resp = await client_session.get(url, headers=headers, raise_for_status=True)    File "/usr/local/lib/python3.10/site-packages/aiohttp/client.py", line 640, in _request      resp.raise_for_status()    File "/usr/local/lib/python3.10/site-packages/aiohttp/client_reqrep.py", line 1004, in raise_for_status      raise ClientResponseError(  aiohttp.client_exceptions.ClientResponseError: 404, message='Not Found', url=URL('https://sqladmin.googleapis.com/sql/v1beta4/projects/sneha-354311/instances/postgres/connectSettings')
2022-07-11 09:12:26 default[20220708t083931]  Task exception was never retrieved
2022-07-11 09:12:26 default[20220708t083931]  future: <Task finished name='Task-72794' coro=<Instance._schedule_refresh.<locals>._refresh_task() done, defined at /usr/local/lib/python3.10/site-packages/google/cloud/sql/connector/instance.py:399> exception=ClientResponseError(RequestInfo(url=URL('https://sqladmin.googleapis.com/sql/v1beta4/projects/sneha-354311/instances/postgres/connectSettings'), method='GET', headers=<CIMultiDictProxy('Host': 'sqladmin.googleapis.com', 'x-goog-api-client': 'cloud-sql-python-connector/0.6.2+pg8000', 'User-Agent': 'cloud-sql-python-connector/0.6.2+pg8000', 'Content-Type': 'application/json', 'Authorization': 'Bearer ya29.c.b0AXv0zTPq4RBL8oRuPHeWtybUPqe_lMg9HfSolPC_NR9PsaNJzlj-sZFI4w-AZuql3sKPwZUpCosNdbL7gAc3F_nWRq-EPzhXekpPQCQCnpv4C2I9xvvVNEw8guCpgbWV3AqmQzGwqEi5JqQPNegJOdF-LwRxVIut7LhmSYBUdGCVYeUcQIG6l4nfjy_Dt2UFAzzaeqNfYdS8Y6onsg.....................................................................................................................................................................................................................................................................................................................................................................................................................................................................................................................................................................................................................................................................................................................................................................................................................................', 'Accept': '*/*', 'Accept-Encoding': 'gzip, deflate')>, real_url=URL('https://sqladmin.googleapis.com/sql/v1beta4/projects/sneha-354311/instances/postgres/connectSettings')), (), status=404, message='Not Found', headers=<CIMultiDictProxy('Vary': 'Origin', 'Vary': 'X-Origin', 'Vary': 'Referer', 'Content-Type': 'application/json; charset=UTF-8', 'Content-Encoding': 'gzip', 'Date': 'Mon, 11 Jul 2022 09:12:26 GMT', 'Server': 'ESF', 'Cache-Control': 'private', 'X-XSS-Protection': '0', 'X-Frame-Options': 'SAMEORIGIN', 'X-Content-Type-Options': 'nosniff', 'Transfer-Encoding': 'chunked')>)>
